Workbook

Sheet Summary
A1: HANNAH PLUMBING & HEATING LTD - LABOUR ONLY PRICING
A2: NLC - Pivot Community Centre (RAAC works) | Client: Procast (David Inch) | Design: Harley Haddow job 313160
A3: Labour only - all materials free-issue by others. Quantities measured from drawings 313160-HAH-XX-00-D-M-05330 P01, 05630 P02, 05230 P02 (tender issue Nov 2025). Prices exclude VAT.
A5: Pricing inputs (yellow cells are editable):
A6: Labour rate per hour (£) | B6: 50 | E6: Same rate as Life Church tender
A7: Wastage / offsets allowance on measured pipe (%) | B7: 0.1 | E7: Covers offsets, crossovers, fittings not shown on 1:100 plans
A8: Contingency on total (%) | B8: 0.05 | E8: Drawings marked 'do not scale' - measured take-off ±10%
A9: Hours per working day | B9: 8 | E9: Used for programme days only
A10: Operatives on site | B10: 2 | E10: Used for programme days only
A12: Section | B12: Labour hrs | C12: Total (£) | D12: % of total | E12: Source
A13: A - Hot & cold water pipework (copper) | B13: =Pipework!G17 -> 275.2882 | C13: =Pipework!I17 -> 13764.41 | D13: =IF($C$21=0,0,C13/$C$21) -> 0.22722076 | E13: Pipework sheet
A14: B - LTHW heating pipework (stainless) | B14: =Pipework!G26 -> 355.0239 | C14: =Pipework!I26 -> 17751.195 | D14: =IF($C$21=0,0,C14/$C$21) -> 0.29303399 | E14: Pipework sheet
A15: C - Above-ground drainage pipework (PVCu) | B15: =Pipework!G34 -> 46.233 | C15: =Pipework!I34 -> 2311.65 | D15: =IF($C$21=0,0,C15/$C$21) -> 0.038160362 | E15: Pipework sheet
A16: D - Preliminaries | B16: ='Fittings & Items'!F8 -> 24 | C16: ='Fittings & Items'!G8 -> 1200 | D16: =IF($C$21=0,0,C16/$C$21) -> 0.019809415 | E16: Fittings & Items sheet
A17: E - Hot & cold water - connections, plant & commissioning | B17: ='Fittings & Items'!F22 -> 165 | C17: ='Fittings & Items'!G22 -> 8250 | D17: =IF($C$21=0,0,C17/$C$21) -> 0.13618973 | E17: Fittings & Items sheet
A18: F - Heating - emitters, valves & commissioning | B18: ='Fittings & Items'!F34 -> 224 | C18: ='Fittings & Items'!G34 -> 11200 | D18: =IF($C$21=0,0,C18/$C$21) -> 0.18488788 | E18: Fittings & Items sheet
A19: G - Drainage - connections & items | B19: ='Fittings & Items'!F47 -> 90 | C19: ='Fittings & Items'!G47 -> 4500 | D19: =IF($C$21=0,0,C19/$C$21) -> 0.074285307 | E19: Fittings & Items sheet
A20: H - Gas (provisional) | B20: ='Fittings & Items'!F53 -> 32 | C20: ='Fittings & Items'!G53 -> 1600 | D20: =IF($C$21=0,0,C20/$C$21) -> 0.026412554 | E20: Fittings & Items sheet
A21: Sub-total | B21: =SUM(B13:B20) -> 1211.5451 | C21: =SUM(C13:C20) -> 60577.255
A22: Contingency | C22: =C21*Summary!$B$8 -> 3028.8627
A23: LABOUR-ONLY TENDER TOTAL (ex VAT) | C23: =C21+C22 -> 63606.118
A25: Total labour hours | B25: =B21 -> 1211.5451
A26: Programme (working days for gang) | B26: =IF(B9*B10=0,0,B21/(B9*B10)) -> 75.721569
A27: Effective £ per man-day | B27: =B6*B9 -> 400
A29: Measured pipework totals (excl. wastage)
A30: Copper - hot, cold & secondary return (m) | B30: =Pipework!D17 -> 816.3
A31: Stainless - LTHW heating (m) | B31: =Pipework!D26 -> 1151.7
A32: PVCu drainage (m) - rough | B32: =Pipework!D34 -> 126
A34: Key qualifications / queries to raise with Procast
A35: • Labour only - all pipe, fittings, valves, brackets, insulation, sanitaryware and plant free-issue by others.
A36: • Heating priced in stainless steel press (per Procast) - drawing notes still say mild steel; stainless OD sizes assumed 42/35/28/22/15.
A37: • Drops to low level assumed 2.5m - ceiling heights not on drawings. Each 0.5m change = approx. ±54m heating / ±27m water.
A38: • Library water feed (22mm H/C/R 'continues to serve library') - route not drawn; excluded, approx. 20m per service if required.
A39: • CWST size discrepancy: drawing 3248x3248x2916 vs schedule 2248x2248x2566 (both 8,000L). Tank erection by supplier assumed.
A40: • Thermal insulation, fire-stopping, builder's work, boxing-in and access hatches by others unless instructed.
A41: • Electrical supplies & interlocks (booster set, fan convectors, gas safety system, panel heaters PH01) by electrician.
A42: • Ventilation (MVHR units, fans, ductwork, cowls) excluded.
A43: • Gas pipe length is PROVISIONAL (30m) - drawing 05430 not measured.
A44: • Take-off measured from tender drawings marked 'do not scale' - accuracy approx. ±10%; re-measure from construction issue.

Sheet Pipework
A1: PIPEWORK - measured take-off and labour build-up
A2: Blue = measured from drawings (edit only if you re-measure). Yellow = labour hours per metre - ESTIMATED norms for install in ceiling void incl. brackets, fittings & valves on the run; adjust to suit your gang.
A4: Ref | B4: Service / description | C4: Size | D4: Measured (m) | E4: Inc. wastage (m) | F4: Hrs / m | G4: Labour hrs | H4: Rate £ / m | I4: Total (£) | J4: Notes
A5: A | B5: HOT & COLD WATER - COPPER (dwg 05330)
A6: A1 | B6: Boosted / tank cold water (BCWS) | C6: 35mm | D6: 27.4 | E6: =D6*(1+Summary!$B$7) -> 30.14 | F6: 0.48 | G6: =E6*F6 -> 14.4672 | H6: =F6*Summary!$B$6 -> 24 | I6: =G6*Summary!$B$6 -> 723.36 | J6: Plant room main + first section of south main
A7: A2 | B7: Boosted / tank cold water (BCWS) | C7: 28mm | D7: 54.9 | E7: =D7*(1+Summary!$B$7) -> 60.39 | F7: 0.38 | G7: =E7*F7 -> 22.9482 | H7: =F7*Summary!$B$6 -> 19 | I7: =G7*Summary!$B$6 -> 1147.41 | J7: East main, east corridor riser, south main lower; incl. 7.5m allowance where drawing is broken at accessible WC
A8: A3 | B8: Boosted / tank cold water (BCWS) | C8: 22mm | D8: 99 | E8: =D8*(1+Summary!$B$7) -> 108.9 | F8: 0.3 | G8: =E8*F8 -> 32.67 | H8: =F8*Summary!$B$6 -> 15 | I8: =G8*Summary!$B$6 -> 1633.5 | J8: Branches + 9 No. 22mm drops @ 2.5m
A9: A4 | B9: Boosted / tank cold water (BCWS) | C9: 15mm | D9: 106.6 | E9: =D9*(1+Summary!$B$7) -> 117.26 | F9: 0.25 | G9: =E9*F9 -> 29.315 | H9: =F9*Summary!$B$6 -> 12.5 | I9: =G9*Summary!$B$6 -> 1465.75 | J9: Tails to fittings + 9 No. 15mm drops @ 2.5m
A10: A5 | B10: Mains cold water (MCWS) - incoming to tank | C10: 35mm | D10: 53.1 | E10: =D10*(1+Summary!$B$7) -> 58.41 | F10: 0.48 | G10: =E10*F10 -> 28.0368 | H10: =F10*Summary!$B$6 -> 24 | I10: =G10*Summary!$B$6 -> 1401.84 | J10: Incoming main rises at SW corner, runs at high level to CWST
A11: A6 | B11: Hot water flow (HWSF) | C11: 35mm | D11: 7 | E11: =D11*(1+Summary!$B$7) -> 7.7 | F11: 0.48 | G11: =E11*F11 -> 3.696 | H11: =F11*Summary!$B$6 -> 24 | I11: =G11*Summary!$B$6 -> 184.8 | J11: Plant room exit (88 l/s section)
A12: A7 | B12: Hot water flow (HWSF) | C12: 28mm | D12: 62 | E12: =D12*(1+Summary!$B$7) -> 68.2 | F12: 0.38 | G12: =E12*F12 -> 25.916 | H12: =F12*Summary!$B$6 -> 19 | I12: =G12*Summary!$B$6 -> 1295.8 | J12: Mains; incl. 7.5m allowance at accessible WC break
A13: A8 | B13: Hot water flow (HWSF) | C13: 22mm | D13: 104.6 | E13: =D13*(1+Summary!$B$7) -> 115.06 | F13: 0.3 | G13: =E13*F13 -> 34.518 | H13: =F13*Summary!$B$6 -> 15 | I13: =G13*Summary!$B$6 -> 1725.9 | J13: Branches + 7 No. 22mm drops @ 2.5m
A14: A9 | B14: Hot water flow (HWSF) | C14: 15mm | D14: 81.5 | E14: =D14*(1+Summary!$B$7) -> 89.65 | F14: 0.25 | G14: =E14*F14 -> 22.4125 | H14: =F14*Summary!$B$6 -> 12.5 | I14: =G14*Summary!$B$6 -> 1120.625 | J14: Tails + 11 No. 15mm drops @ 2.5m
A15: A10 | B15: Secondary return (HWSR) | C15: 22mm | D15: 13.7 | E15: =D15*(1+Summary!$B$7) -> 15.07 | F15: 0.3 | G15: =E15*F15 -> 4.521 | H15: =F15*Summary!$B$6 -> 15 | I15: =G15*Summary!$B$6 -> 226.05 | J15: Plant room section
A16: A11 | B16: Secondary return (HWSR) | C16: 15mm | D16: 206.5 | E16: =D16*(1+Summary!$B$7) -> 227.15 | F16: 0.25 | G16: =E16*F16 -> 56.7875 | H16: =F16*Summary!$B$6 -> 12.5 | I16: =G16*Summary!$B$6 -> 2839.375 | J16: Return throughout + 18 No. drops @ 2.5m + 7.5m break allowance
B17: Sub-total A | D17: =SUM(D6:D16) -> 816.3 | E17: =SUM(E6:E16) -> 897.93 | G17: =SUM(G6:G16) -> 275.2882 | I17: =SUM(I6:I16) -> 13764.41
A19: B | B19: LTHW HEATING - STAINLESS STEEL PRESS (dwg 05630)
A20: B1 | B20: LTHW flow & return (VT circuit from plant) | C20: 42mm (40NB) | D20: 95.1 | E20: =D20*(1+Summary!$B$7) -> 104.61 | F20: 0.5 | G20: =E20*F20 -> 52.305 | H20: =F20*Summary!$B$6 -> 25 | I20: =G20*Summary!$B$6 -> 2615.25 | J20: Drawing sizes are steel NB - stainless OD equivalent shown; confirm with Procast
A21: B2 | B21: LTHW flow & return | C21: 35mm (32NB) | D21: 128.6 | E21: =D21*(1+Summary!$B$7) -> 141.46 | F21: 0.42 | G21: =E21*F21 -> 59.4132 | H21: =F21*Summary!$B$6 -> 21 | I21: =G21*Summary!$B$6 -> 2970.66 | J21: VT to library, kitchen branch, south main
A22: B3 | B22: LTHW flow & return (CT circuit) | C22: 28mm (25NB) | D22: 83.7 | E22: =D22*(1+Summary!$B$7) -> 92.07 | F22: 0.33 | G22: =E22*F22 -> 30.3831 | H22: =F22*Summary!$B$6 -> 16.5 | I22: =G22*Summary!$B$6 -> 1519.155 | J22: CT to library + south main section
A23: B4 | B23: LTHW flow & return | C23: 22mm (20NB) | D23: 156.4 | E23: =D23*(1+Summary!$B$7) -> 172.04 | F23: 0.27 | G23: =E23*F23 -> 46.4508 | H23: =F23*Summary!$B$6 -> 13.5 | I23: =G23*Summary!$B$6 -> 2322.54 | J23: Sub-mains / branches
A24: B5 | B24: LTHW flow & return - branches & low-level runs | C24: 15mm | D24: 417.9 | E24: =D24*(1+Summary!$B$7) -> 459.69 | F24: 0.22 | G24: =E24*F24 -> 101.1318 | H24: =F24*Summary!$B$6 -> 11 | I24: =G24*Summary!$B$6 -> 5056.59 | J24: Branches to radiators / fan convectors
A25: B6 | B25: LTHW drops to emitters (F&R) | C25: 15mm | D25: 270 | E25: =D25*(1+Summary!$B$7) -> 297 | F25: 0.22 | G25: =E25*F25 -> 65.34 | H25: =F25*Summary!$B$6 -> 11 | I25: =G25*Summary!$B$6 -> 3267 | J25: 54 emitters x 2 pipes x 2.5m assumed drop - ceiling height not on drawings
B26: Sub-total B | D26: =SUM(D20:D25) -> 1151.7 | E26: =SUM(E20:E25) -> 1266.87 | G26: =SUM(G20:G25) -> 355.0239 | I26: =SUM(I20:I25) -> 17751.195
A28: C | B28: ABOVE GROUND DRAINAGE - PVCu (dwg 05230) - ROUGH
A29: C1 | B29: Soil branches (horizontal) | C29: 110mm | D29: 25 | E29: =D29*(1+Summary!$B$7) -> 27.5 | F29: 0.35 | G29: =E29*F29 -> 9.625 | H29: =F29*Summary!$B$6 -> 17.5 | I29: =G29*Summary!$B$6 -> 481.25 | J29: Approx. split of ~61m measured horizontal drainage
A30: C2 | B30: Waste branches | C30: 40mm | D30: 12 | E30: =D30*(1+Summary!$B$7) -> 13.2 | F30: 0.25 | G30: =E30*F30 -> 3.3 | H30: =F30*Summary!$B$6 -> 12.5 | I30: =G30*Summary!$B$6 -> 165 | J30: Approx. split
A31: C3 | B31: Waste branches | C31: 32mm | D31: 24 | E31: =D31*(1+Summary!$B$7) -> 26.4 | F31: 0.22 | G31: =E31*F31 -> 5.808 | H31: =F31*Summary!$B$6 -> 11 | I31: =G31*Summary!$B$6 -> 290.4 | J31: Approx. split
A32: C4 | B32: Pre-insulated SVPs (11 No. through roof) | C32: 110mm | D32: 55 | E32: =D32*(1+Summary!$B$7) -> 60.5 | F32: 0.4 | G32: =E32*F32 -> 24.2 | H32: =F32*Summary!$B$6 -> 20 | I32: =G32*Summary!$B$6 -> 1210 | J32: 11 stacks x ~5m assumed (ground to above roof)
A33: C5 | B33: Stub stacks (8 No.) | C33: 50/75mm | D33: 10 | E33: =D33*(1+Summary!$B$7) -> 11 | F33: 0.3 | G33: =E33*F33 -> 3.3 | H33: =F33*Summary!$B$6 -> 15 | I33: =G33*Summary!$B$6 -> 165 | J33: 8 stub stacks x ~1.2m
B34: Sub-total C | D34: =SUM(D29:D33) -> 126 | E34: =SUM(E29:E33) -> 138.6 | G34: =SUM(G29:G33) -> 46.233 | I34: =SUM(I29:I33) -> 2311.65

Sheet Fittings & Items
A1: FITTINGS, PLANT, CONNECTIONS & COMMISSIONING - labour build-up
A2: Blue quantities are counted from the drawings / schedules. Yellow hours per item are ESTIMATES - adjust to suit. Set qty to 0 to omit an item.
A4: Ref | B4: Description | C4: Unit | D4: Qty | E4: Hrs each | F4: Labour hrs | G4: Total (£) | H4: Notes / qualifications
A5: D | B5: PRELIMINARIES
A6: D1 | B6: RAMS, inductions, site set-up, setting out & co-ordination drawings | C6: item | D6: 1 | E6: 16 | F6: =D6*E6 -> 16 | G6: =F6*Summary!$B$6 -> 800 | H6: Contractor to produce co-ordinated installation drawings (dwg note)
A7: D2 | B7: Pre-start survey of existing M&E services (required by dwg notes) | C7: item | D7: 1 | E7: 8 | F7: =D7*E7 -> 8 | G7: =F7*Summary!$B$6 -> 400
B8: Sub-total D | F8: =SUM(F6:F7) -> 24 | G8: =SUM(G6:G7) -> 1200
A10: E | B10: HOT & COLD WATER - CONNECTIONS & PLANT
A11: E1 | B11: Connect WC (cold feed, isolation valve) | C11: no | D11: 27 | E11: 0.75 | F11: =D11*E11 -> 20.25 | G11: =F11*Summary!$B$6 -> 1012.5 | H11: Count from drainage notes; sanitaryware fixing NOT included - confirm whose scope
A12: E2 | B12: Connect WHB incl. TMV3 (Oventrop Brawa-mix), isolation, strainers | C12: no | D12: 24 | E12: 1.75 | F12: =D12*E12 -> 42 | G12: =F12*Summary!$B$6 -> 2100 | H12: TMV to every WHB & sink per dwg note 16
A13: E3 | B13: Connect sink incl. TMV3, isolation | C13: no | D13: 7 | E13: 1.75 | F13: =D13*E13 -> 12.25 | G13: =F13*Summary!$B$6 -> 612.5
A14: E4 | B14: Connect shower (H&C, isolation) | C14: no | D14: 11 | E14: 1.5 | F14: =D14*E14 -> 16.5 | G14: =F14*Summary!$B$6 -> 825 | H14: Shower valves assumed thermostatic; check spec
A15: E5 | B15: Hot water return commissioning valves (Oventrop Aquastrom T Plus) | C15: no | D15: 18 | E15: 0.5 | F15: =D15*E15 -> 9 | G15: =F15*Summary!$B$6 -> 450 | H15: One per drop assumed
A16: E6 | B16: Install & connect booster set BP01 (Grundfos Hydro Multi-E) on AV mounts, flexible connections | C16: item | D16: 1 | E16: 12 | F16: =D16*E16 -> 12 | G16: =F16*Summary!$B$6 -> 600 | H16: Electrical supply by others
A17: E7 | B17: Connect 8,000L CWST - float valve, outlets, screened overflow / warning / drain-down | C17: item | D17: 1 | E17: 16 | F17: =D17*E17 -> 16 | G17: =F17*Summary!$B$6 -> 800 | H17: Tank erection by tank supplier assumed - CHECK. Tank size discrepancy dwg 3248 vs schedule 2248
A18: E8 | B18: Plant room pipework not shown on plan (35 suction, 54 overflow/drain, 28 warning) | C18: m | D18: 20 | E18: 0.45 | F18: =D18*E18 -> 9 | G18: =F18*Summary!$B$6 -> 450 | H18: Allowance only - schematic on drawing
A19: E9 | B19: Tie-in to existing water services / incoming main | C19: no | D19: 2 | E19: 4 | F19: =D19*E19 -> 8 | G19: =F19*Summary!$B$6 -> 400
A20: E10 | B20: Pipework labelling to BS 1710 | C20: item | D20: 1 | E20: 8 | F20: =D20*E20 -> 8 | G20: =F20*Summary!$B$6 -> 400
A21: E11 | B21: Pressure test, flush, chlorinate & certify (BS EN 806 / L8) | C21: item | D21: 1 | E21: 12 | F21: =D21*E21 -> 12 | G21: =F21*Summary!$B$6 -> 600 | H21: Lab sample fee by others (labour only)
B22: Sub-total E | F22: =SUM(F11:F21) -> 165 | G22: =SUM(G11:G21) -> 8250
A24: F | B24: HEATING - EMITTERS, VALVES, COMMISSIONING
A25: F1 | B25: Hang & connect LST radiator incl. TRV, LSV, cover (R01-R20) | C25: no | D25: 48 | E25: 2.5 | F25: =D25*E25 -> 120 | G25: =F25*Summary!$B$6 -> 6000 | H25: Merriot Protecta - qty from equipment schedule
A26: F2 | B26: Hang & connect fan convector (FC01 x5, FC02 x1) incl. remote-sensor TRV | C26: no | D26: 6 | E26: 3 | F26: =D26*E26 -> 18 | G26: =F26*Summary!$B$6 -> 900 | H26: Electrical connection by others
A27: F3 | B27: Commissioning sets CS01-CS10 | C27: no | D27: 10 | E27: 1.5 | F27: =D27*E27 -> 15 | G27: =F27*Summary!$B$6 -> 750
A28: F4 | B28: Branch isolation valves (pairs) - on drops/branches | C28: pair | D28: 30 | E28: 0.5 | F28: =D28*E28 -> 15 | G28: =F28*Summary!$B$6 -> 750 | H28: Approx. count from dwg 05630 - verify
A29: F5 | B29: AAVs at high points / drain cocks at low points | C29: no | D29: 20 | E29: 0.4 | F29: =D29*E29 -> 8 | G29: =F29*Summary!$B$6 -> 400 | H29: Allowance
A30: F6 | B30: Tie-in to existing LTHW in plant room (CT & VT circuits) | C30: no | D30: 2 | E30: 6 | F30: =D30*E30 -> 12 | G30: =F30*Summary!$B$6 -> 600 | H30: Drain-down / refill of existing system included
A31: F7 | B31: Tie-in to existing pipework in library (CT & VT) | C31: no | D31: 2 | E31: 4 | F31: =D31*E31 -> 8 | G31: =F31*Summary!$B$6 -> 400
A32: F8 | B32: Tie-in fan convector circuit to existing in plant room | C32: no | D32: 1 | E32: 4 | F32: =D32*E32 -> 4 | G32: =F32*Summary!$B$6 -> 200
A33: F9 | B33: Pressure test, flush, fill, vent, balance & commission | C33: item | D33: 1 | E33: 24 | F33: =D33*E33 -> 24 | G33: =F33*Summary!$B$6 -> 1200 | H33: Water treatment chemicals by others
B34: Sub-total F | F34: =SUM(F25:F33) -> 224 | G34: =SUM(G25:G33) -> 11200
A36: G | B36: DRAINAGE - ITEMS
A37: G1 | B37: SVP roof termination - weather collar & bird cage, access door | C37: no | D37: 11 | E37: 1.5 | F37: =D37*E37 -> 16.5 | G37: =F37*Summary!$B$6 -> 825 | H37: Weathering by roofer (dwg note 10)
A38: G2 | B38: Stub stack AAV & access, connect to below-ground | C38: no | D38: 8 | E38: 1 | F38: =D38*E38 -> 8 | G38: =F38*Summary!$B$6 -> 400
A39: G3 | B39: 110mm pop-up connection to below-ground | C39: no | D39: 2 | E39: 1 | F39: =D39*E39 -> 2 | G39: =F39*Summary!$B$6 -> 100
A40: G4 | B40: WC pan connection | C40: no | D40: 27 | E40: 0.5 | F40: =D40*E40 -> 13.5 | G40: =F40*Summary!$B$6 -> 675
A41: G5 | B41: Basin / sink trap & waste connection | C41: no | D41: 31 | E41: 0.5 | F41: =D41*E41 -> 15.5 | G41: =F41*Summary!$B$6 -> 775 | H41: 24 WHB + 7 sinks
A42: G6 | B42: Shower gully - install & connect to existing BG pop-up | C42: no | D42: 11 | E42: 1.5 | F42: =D42*E42 -> 16.5 | G42: =F42*Summary!$B$6 -> 825
A43: G7 | B43: Grease separator on kitchen drainage line (install & connect) | C43: no | D43: 1 | E43: 4 | F43: =D43*E43 -> 4 | G43: =F43*Summary!$B$6 -> 200 | H43: Unit supply & sizing by others
A44: G8 | B44: Condensate tundishes / waterless traps to SVP | C44: no | D44: 4 | E44: 0.75 | F44: =D44*E44 -> 3 | G44: =F44*Summary!$B$6 -> 150 | H44: Allowance
...
